<robot name="bookcase">
  <!--
       Expedit shelving unit - Birch effect
       IKEA #501.030.86
    -->
    <!-- Ok, what does an external Translation tag do for all body's/links? -->
    <link name="bookcase">
        <!-- Side walls -->
        <visual name="wall1">
            <geometry>
                <box size="0.025 0.695 0.195"/>
                <material>
                    <color rgba="0.968 0.901 0.709 0"/>
                </material>
            </geometry>
            <origin xyz="-0.368 0 0"/>
        </visual>
        <visual name="wall2">
            <geometry>
                <box size="0.025 0.695 0.195"/>
                <material>
                    <color rgba="0.968 0.901 0.709 0"/>
                </material>
            </geometry>
            <origin xyz="0.368 0 0"/>
        </visual>

        <!-- Top and bottom walls -->
        <visual name="wall3">
            <geometry>
                <box size="0.394 0.025 0.196"/>
                <material>
                    <color rgba="0.968 0.901 0.709 0"/>
                </material>
            </geometry>
            <origin xyz="0 -0.72 0"/>
        </visual>
        <visual name="wall4">
            <geometry>
                <box size="0.394 0.025 0.196"/>
                <material>
                    <color rgba="0.968 0.901 0.709 0"/>
                </material>
            </geometry>
            <origin xyz="0 0.72 0"/>
        </visual>
        <!-- Horizonal shelf inserts -->
        <visual name="hinsert1">
            <geometry>
                <box size="0.343 0.0075 0.194"/>
                <material>
                    <color rgba="0.968 0.901 0.709 0"/>
                </material>
            </geometry>
            <origin xyz="0 0.35125 0"/>
        </visual>
        <visual name="hinsert2">
            <geometry>
                <box size="0.343 0.0075 0.194"/>
                <material>
                    <color rgba="0.968 0.901 0.709 0"/>
                </material>
            </geometry>
            <origin xyz="0 0 0"/>
        </visual>

        <visual name="hinsert3">
            <geometry>
                <box size="0.343 0.0075 0.194"/>
                <material>
                    <color rgba="0.968 0.901 0.709 0"/>
                </material>
            </geometry>
            <origin xyz="0 -0.35125 0"/>
        </visual>
        <!-- vertical shelf inserts -->
        <visual name="vinsert1">
            <geometry>
                <box size="0.0075 0.168125 0.193"/>
                <material>
                    <color rgba="0.968 0.901 0.709 0"/>
                </material>
            </geometry>
            <origin xyz="0 0.175625 0"/>
        </visual>
        <visual name="vinsert2">
            <geometry>
                <box size="0.0075 0.168125 0.193"/>
                <material>
                    <color rgba="0.968 0.901 0.709 0"/>
                </material>
            </geometry>
            <origin xyz="0 -0.175625 0"/>
        </visual>
        <visual name="vinsert3">
            <geometry>
                <box size="0.0075 0.168125 0.193"/>
                <material>
                    <color rgba="0.968 0.901 0.709 0"/>
                </material>
            </geometry>
            <origin xyz="0 -0.526875 0"/>
        </visual>
    </link>

    <link name="padding_bookcase">
        <!-- side walls -->
        <visual name="pwall1">
            <geometry>
                <box size="0.075 0.745 0.245"/>
                <material>
                    <color rgba="0.968 0.901 0.709 1"/>
                </material>
            </geometry>
            <origin xyz="-0.368 0 0"/>
        </visual>
        <visual name="pwall2">
            <geometry>
                <box size="0.075 0.745 0.245"/>
                <material>
                    <color rgba="0.968 0.901 0.709 1"/>
                </material>
            </geometry>
            <origin xyz="0.368 0 0"/>
        </visual>

        <!-- Top and bottom walls -->
        <visual name="pwall3">
            <geometry>
                <box size="0.444 0.075 0.246"/>
                <material>
                    <color rgba="0.968 0.901 0.709 1"/>
                </material>
            </geometry>
            <origin xyz="0 -0.72 0"/>
        </visual>
        <visual name="pwall4">
            <geometry>
                <box size="0.444 0.075 0.246"/>
                <material>
                    <color rgba="0.968 0.901 0.709 1.0"/>
                </material>
            </geometry>
            <origin xyz="0 0.72 0"/>
        </visual>
        <!-- Horizonal shelf inserts -->
        <visual name="phinsert1">
            <geometry>
                <box size="0.393 0.0575 0.244"/>
                <material>
                    <color rgba="0.968 0.901 0.709 1"/>
                </material>
            </geometry>
            <origin xyz="0 0.35125 0"/>
        </visual>
        <visual name="phinsert2">
            <geometry>
                <box size="0.393 0.0575 0.244"/>
                <material>
                    <color rgba="0.968 0.901 0.709 1"/>
                </material>
            </geometry>
            <origin xyz="0 0 0"/>
        </visual>

        <visual name="phinsert3">
            <geometry>
                <box size="0.393 0.0575 0.244"/>
                <material>
                    <color rgba="0.968 0.901 0.709 1"/>
                </material>
            </geometry>
            <origin xyz="0 -0.35125 0"/>
        </visual>
        <!-- vertical shelf inserts -->
        <visual name="pvinsert1">
            <geometry>
                <box size="0.0575 0.218125 0.243"/>
                <material>
                    <color rgba="0.968 0.901 0.709 1"/>
                </material>
            </geometry>
            <origin xyz="0 0.175625 0"/>
        </visual>
        <visual name="pvinsert2">
            <geometry>
                <box size="0.0575 0.218125 0.243"/>
                <material>
                    <color rgba="0.968 0.901 0.709 1"/>
                </material>
            </geometry>
            <origin xyz="0 -0.175625 0"/>
        </visual>
        <visual name="pvinsert3">
            <geometry>
                <box size="0.0575 0.218125 0.243"/>
                <material>
                    <color rgba="0.968 0.901 0.709 1"/>
                </material>
            </geometry>
            <origin xyz="0 -0.526875 0"/>
        </visual>
    </link>

    <joint name="bookcase" type="continuous">
        <parent link="bookcase"/>
        <child link="padding_bookcase"/>
    </joint>
</robot>
